<?xml version="1.0" ?>
<robot name="Robot">
  <!--Generated by RobotCAD, a ROS Workbench for FreeCAD (https://github.com/drfenixion/freecad.robotcad)-->
  <link name="waist">
    <visual>
      <!--waist001/waist001.-->
      <origin rpy="0 0 0" xyz="0.0 0.0 0.382"/>
      <geometry>
        <box size="0.05 0.12 0.04"/>
      </geometry>
    </visual>
  </link>
  <link name="body">
    <visual>
      <!--body001/body001.-->
      <origin rpy="0 0 0" xyz="0.0 0.0 0.05"/>
      <geometry>
        <box size="0.05 0.073 0.1"/>
      </geometry>
    </visual>
    <visual>
      <!--body001/body_sholder001.-->
      <origin rpy="0 0 0" xyz="0.0 0.0 0.1205"/>
      <geometry>
        <box size="0.04 0.143 0.04"/>
      </geometry>
    </visual>
    <visual>
      <!--body001/Link002.-->
      <origin rpy="0 0 0" xyz="0.01 -0.0015 0.151"/>
      <geometry>
        <box size="0.02 0.02 0.02"/>
      </geometry>
    </visual>
  </link>
  <link name="r_hip">
    <visual>
      <!--right_hip001/right_hip001.-->
      <origin rpy="0 1.5707963267948963 0" xyz="0.0 0.0 0.0"/>
      <geometry>
        <sphere radius="0.02"/>
      </geometry>
    </visual>
  </link>
  <link name="r_thigh">
    <visual>
      <!--right_thigh001/right_thigh001.-->
      <origin rpy="-1.5707963267948957 0 -1.5707963267948963" xyz="-0.05 0.0 0.0"/>
      <geometry>
        <box size="0.06 0.04 0.12"/>
      </geometry>
    </visual>
  </link>
  <link name="r_knee">
    <visual>
      <!--right_knee001/right_knee001.-->
      <origin rpy="-1.5707963267948974 0 -1.5707963267948977" xyz="-0.0235 0.0 0.0"/>
      <geometry>
        <box size="0.06 0.04 0.047"/>
      </geometry>
    </visual>
  </link>
  <link name="r_shin">
    <visual>
      <!--right_shin001/right_shin001.-->
      <origin rpy="1.5707963267948963 0 1.5707963267948966" xyz="-0.05 0.0 0.0"/>
      <geometry>
        <box size="0.06 0.04 0.12"/>
      </geometry>
    </visual>
  </link>
  <link name="r_ankle">
    <visual>
      <!--right_ankle001/right_ankle001.-->
      <origin rpy="1.5707963267948966 0 1.5707963267948977" xyz="-0.035 0.0 0.0"/>
      <geometry>
        <sphere radius="0.02"/>
      </geometry>
    </visual>
  </link>
  <link name="r_sole">
    <visual>
      <!--right_sole001/right_sole001.-->
      <origin rpy="0 1.5707963267948963 0" xyz="-0.04 0.0 0.0"/>
      <geometry>
        <box size="0.14 0.09 0.01"/>
      </geometry>
    </visual>
  </link>
  <link name="l_hip">
    <visual>
      <!--left_hip001/left_hip001.-->
      <origin rpy="0 0 0" xyz="0.0 0.0 0.0"/>
      <geometry>
        <sphere radius="0.02"/>
      </geometry>
    </visual>
  </link>
  <link name="l_thigh">
    <visual>
      <!--left_thigh001/left_thigh001.-->
      <origin rpy="-1.570796326794897 0 -1.5707963267948966" xyz="-0.05 0.0 0.0"/>
      <geometry>
        <box size="0.06 0.04 0.12"/>
      </geometry>
    </visual>
  </link>
  <link name="l_knee">
    <visual>
      <!--left_knee001/left_knee001.-->
      <origin rpy="-1.570796326794897 0 -1.5707963267948966" xyz="-0.0235 0.0 0.0"/>
      <geometry>
        <box size="0.06 0.04 0.047"/>
      </geometry>
    </visual>
  </link>
  <link name="l_shin">
    <visual>
      <!--left_shin001/left_shin001.-->
      <origin rpy="-1.5707963267948977 0 -1.570796326794897" xyz="-0.05 0.0 0.0"/>
      <geometry>
        <box size="0.06 0.04 0.12"/>
      </geometry>
    </visual>
  </link>
  <link name="l_ankle">
    <visual>
      <!--left_ankle001/left_ankle001.-->
      <origin rpy="0 0 0" xyz="-0.035 0.0 0.0"/>
      <geometry>
        <sphere radius="0.02"/>
      </geometry>
    </visual>
  </link>
  <link name="l_sole">
    <visual>
      <!--left_sole001/left_sole001.-->
      <origin rpy="0 1.570796326794895 0" xyz="-0.04 0.0 0.0"/>
      <geometry>
        <box size="0.14 0.09 0.01"/>
      </geometry>
    </visual>
  </link>
  <link name="r_p_sholder"/>
  <link name="r_r_sholder">
    <visual>
      <!--right_arm001/right_arm001.-->
      <origin rpy="-1.5707963267948974 1.5707963267948961 0" xyz="0.0 -0.0225 0.0"/>
      <geometry>
        <box size="0.04 0.04 0.08"/>
      </geometry>
    </visual>
  </link>
  <link name="r_y_wrist"/>
  <link name="r_r_wrist">
    <visual>
      <!--right_wrist001/right_wrist001.-->
      <origin rpy="1.570796326794897 -1.5707963267948963 0" xyz="0.0 0.0 0.0"/>
      <geometry>
        <box size="0.04 0.04 0.04"/>
      </geometry>
    </visual>
  </link>
  <link name="r_hand">
    <visual>
      <!--right_hand001/right_hand001.-->
      <origin rpy="1.5707963267948968 0 -3.141592653589793" xyz="-0.065 -0.005 0.004"/>
      <geometry>
        <box size="0.17 0.002 0.16"/>
      </geometry>
    </visual>
  </link>
  <link name="l_p_sholder"/>
  <link name="l_r_sholder">
    <visual>
      <!--left_arm001/left_arm001.-->
      <origin rpy="-1.5707963267948966 -1.570796326794896 0" xyz="0.0 -0.0225 0.0"/>
      <geometry>
        <box size="0.04 0.04 0.08"/>
      </geometry>
    </visual>
  </link>
  <link name="l_y_wrist"/>
  <link name="l_r_wrist">
    <visual>
      <!--left_wrist001/left_wrist001.-->
      <origin rpy="1.570796326794897 1.5707963267948961 0" xyz="0.0 0.0 0.0"/>
      <geometry>
        <box size="0.04 0.04 0.04"/>
      </geometry>
    </visual>
  </link>
  <link name="l_hand">
    <visual>
      <!--left_hand001/left_hand001.-->
      <origin rpy="1.5707963267948974 0 -1.5707963267948966" xyz="0.005 -0.065 0.004"/>
      <geometry>
        <box size="0.17 0.002 0.16"/>
      </geometry>
    </visual>
  </link>
  <joint name="waist_joint" type="revolute">
    <parent link="waist"/>
    <child link="body"/>
    <origin rpy="0 0 0" xyz="0.0 0.0 0.4045"/>
    <axis xyz="0 0 1"/>
    <limit effort="0.0" lower="-1.5707963267948966" upper="1.5707963267948966" velocity="0.0"/>
  </joint>
  <joint name="r_hip_joint" type="revolute">
    <parent link="waist"/>
    <child link="r_hip"/>
    <origin rpy="0 -1.5707963267948963 0" xyz="0.0 -0.052 0.362"/>
    <axis xyz="0 0 1"/>
    <limit effort="0.0" lower="-1.5707963267948966" upper="1.5707963267948966" velocity="0.0"/>
  </joint>
  <joint name="r_thigh_top_joint" type="revolute">
    <parent link="r_hip"/>
    <child link="r_thigh"/>
    <origin rpy="1.5707963267948968 0 0" xyz="-0.035 0.0 0.0"/>
    <axis xyz="0 0 1"/>
    <limit effort="0.0" lower="-1.5707963267948966" upper="1.5707963267948966" velocity="0.0"/>
  </joint>
  <joint name="r_thigh_bottom_joint" type="revolute">
    <parent link="r_thigh"/>
    <child link="r_knee"/>
    <origin rpy="0 0 0" xyz="-0.1 0.0 0.0"/>
    <axis xyz="0 0 1"/>
    <limit effort="0.0" lower="-1.5707963267948966" upper="1.5707963267948966" velocity="0.0"/>
    <mimic joint="r_thigh_top_joint" multiplier="-1.0" offset="0.0"/>
  </joint>
  <joint name="r_shin_top_joint" type="revolute">
    <parent link="r_knee"/>
    <child link="r_shin"/>
    <origin rpy="3.141592653589793 0 0" xyz="-0.047 0.0 0.0"/>
    <axis xyz="0 0 1"/>
    <limit effort="0.0" lower="-1.5707963267948966" upper="1.5707963267948966" velocity="0.0"/>
  </joint>
  <joint name="r_shin_bottom_joint" type="revolute">
    <parent link="r_shin"/>
    <child link="r_ankle"/>
    <origin rpy="0 0 0" xyz="-0.1 0.0 0.0"/>
    <axis xyz="0 0 1"/>
    <limit effort="0.0" lower="-1.5707963267948966" upper="1.5707963267948966" velocity="0.0"/>
    <mimic joint="r_shin_top_joint" multiplier="-1.0" offset="0.0"/>
  </joint>
  <joint name="r_ankle_joint" type="revolute">
    <parent link="r_ankle"/>
    <child link="r_sole"/>
    <origin rpy="-1.5707963267948968 0 0" xyz="-0.035 0.0 0.0"/>
    <axis xyz="0 0 1"/>
    <limit effort="0.0" lower="-1.5707963267948966" upper="1.5707963267948966" velocity="0.0"/>
  </joint>
  <joint name="l_hip_joint" type="revolute">
    <parent link="waist"/>
    <child link="l_hip"/>
    <origin rpy="3.141592653589793 -1.5707963267948963 0" xyz="0.0 0.052 0.362"/>
    <axis xyz="0 0 1"/>
    <limit effort="0.0" lower="-1.5707963267948966" upper="1.5707963267948966" velocity="0.0"/>
  </joint>
  <joint name="l_thigh_top_joint" type="revolute">
    <parent link="l_hip"/>
    <child link="l_thigh"/>
    <origin rpy="-1.5707963267948968 0 0" xyz="-0.035 0.0 0.0"/>
    <axis xyz="0 0 1"/>
    <limit effort="0.0" lower="-1.5707963267948966" upper="1.5707963267948966" velocity="0.0"/>
  </joint>
  <joint name="l_thigh_bottom_joint" type="revolute">
    <parent link="l_thigh"/>
    <child link="l_knee"/>
    <origin rpy="0 0 0" xyz="-0.1 0.0 0.0"/>
    <axis xyz="0 0 1"/>
    <limit effort="0.0" lower="-1.5707963267948966" upper="1.5707963267948966" velocity="0.0"/>
    <mimic joint="l_thigh_top_joint" multiplier="-1.0" offset="0.0"/>
  </joint>
  <joint name="l_shin_top_joint" type="revolute">
    <parent link="l_knee"/>
    <child link="l_shin"/>
    <origin rpy="0 0 0" xyz="-0.047 0.0 0.0"/>
    <axis xyz="0 0 1"/>
    <limit effort="0.0" lower="-1.5707963267948966" upper="1.5707963267948966" velocity="0.0"/>
  </joint>
  <joint name="l_shin_bottom_joint" type="revolute">
    <parent link="l_shin"/>
    <child link="l_ankle"/>
    <origin rpy="0 0 0" xyz="-0.1 0.0 0.0"/>
    <axis xyz="0 0 1"/>
    <limit effort="0.0" lower="-1.5707963267948966" upper="1.5707963267948966" velocity="0.0"/>
    <mimic joint="l_shin_top_joint" multiplier="-1.0" offset="0.0"/>
  </joint>
  <joint name="l_ankle_joint" type="revolute">
    <parent link="l_ankle"/>
    <child link="l_sole"/>
    <origin rpy="-1.5707963267948968 0 0" xyz="-0.035 0.0 0.0"/>
    <axis xyz="0 0 1"/>
    <limit effort="0.0" lower="-1.5707963267948966" upper="1.5707963267948966" velocity="0.0"/>
  </joint>
  <joint name="r_p_sholder_joint" type="revolute">
    <parent link="body"/>
    <child link="r_p_sholder"/>
    <origin rpy="1.5707963267948968 0 0" xyz="0.0 -0.0715 0.1205"/>
    <axis xyz="0 0 1"/>
    <limit effort="0.0" lower="-1.5707963267948966" upper="1.5707963267948966" velocity="0.0"/>
  </joint>
  <joint name="r_r_sholder_joint" type="revolute">
    <parent link="r_p_sholder"/>
    <child link="r_r_sholder"/>
    <origin rpy="0 -1.5707963267948963 0" xyz="0.0 0.0 0.02"/>
    <axis xyz="0 0 1"/>
    <limit effort="0.0" lower="-1.5707963267948966" upper="1.5707963267948966" velocity="0.0"/>
  </joint>
  <joint name="r_y_wrist_joint" type="revolute">
    <parent link="r_r_sholder"/>
    <child link="r_y_wrist"/>
    <origin rpy="-1.5707963267948968 0 0" xyz="0.0 -0.07 0.0"/>
    <axis xyz="0 0 1"/>
    <limit effort="0.0" lower="-1.5707963267948966" upper="1.5707963267948966" velocity="0.0"/>
  </joint>
  <joint name="r_r_wrist_joint" type="revolute">
    <parent link="r_y_wrist"/>
    <child link="r_r_wrist"/>
    <origin rpy="-1.5707963267948968 0 0" xyz="0.0 0.0 -0.033"/>
    <axis xyz="0 0 1"/>
    <limit effort="0.0" lower="0.0" upper="3.141592653589793" velocity="0.0"/>
  </joint>
  <joint name="r_hand_joint" type="revolute">
    <parent link="r_r_wrist"/>
    <child link="r_hand"/>
    <origin rpy="1.5707963267948966 0 1.5707963267948966" xyz="0.02 0.0 0.0"/>
    <axis xyz="0 0 1"/>
    <limit effort="0.0" lower="-1.5707963267948966" upper="1.5707963267948966" velocity="0.0"/>
  </joint>
  <joint name="l_p_sholder_joint" type="revolute">
    <parent link="body"/>
    <child link="l_p_sholder"/>
    <origin rpy="1.5707963267948968 0 0" xyz="0.0 0.0715 0.1205"/>
    <axis xyz="0 0 1"/>
    <limit effort="0.0" lower="-1.5707963267948966" upper="1.5707963267948966" velocity="0.0"/>
  </joint>
  <joint name="l_r_sholder_joint" type="revolute">
    <parent link="l_p_sholder"/>
    <child link="l_r_sholder"/>
    <origin rpy="0 1.5707963267948963 0" xyz="0.0 0.0 -0.02"/>
    <axis xyz="0 0 1"/>
    <limit effort="0.0" lower="-1.5707963267948966" upper="1.5707963267948966" velocity="0.0"/>
  </joint>
  <joint name="l_y_wrist_joint" type="revolute">
    <parent link="l_r_sholder"/>
    <child link="l_y_wrist"/>
    <origin rpy="1.5707963267948968 0 0" xyz="0.0 -0.07 0.0"/>
    <axis xyz="0 0 1"/>
    <limit effort="0.0" lower="-1.5707963267948966" upper="1.5707963267948966" velocity="0.0"/>
  </joint>
  <joint name="l_r_wrist_joint" type="revolute">
    <parent link="l_y_wrist"/>
    <child link="l_r_wrist"/>
    <origin rpy="1.5707963267948968 0 0" xyz="0.0 0.0 0.033"/>
    <axis xyz="0 0 1"/>
    <limit effort="0.0" lower="0.0" upper="3.141592653589793" velocity="0.0"/>
  </joint>
  <joint name="l_hand_joint" type="revolute">
    <parent link="l_r_wrist"/>
    <child link="l_hand"/>
    <origin rpy="0 1.5707963267948963 0" xyz="0.02 0.0 0.0"/>
    <axis xyz="0 0 1"/>
    <limit effort="0.0" lower="-1.5707963267948966" upper="1.5707963267948966" velocity="0.0"/>
  </joint>
</robot>
